<?xml version="1.0" ?>
<!-- MIT License

Copyright (c) 2024 JD edu. http://jdedu.kr author: conner.jeong@gmail.com

Permission is hereby granted, free of charge, to any person obtaining a copy
of this software and associated documentation files (the "Software"), to deal
in the Software without restriction, including without limitation the rights
to use, copy, modify, merge, publish, distribute, sublicense, and/or sell
copies of the Software, and to permit persons to whom the Software is
furnished to do so, subject to the following conditions:

The above copyright notice and this permission notice shall be included in all
copies or substantial portions of the Software.

THE SOFTWARE IS PROVIDED "AS IS", WITHOUT WARRANTY OF ANY KIND, EXPRESS OR
IMPLIED, INCLUDING BUT NOT LIMITED TO THE WARRANTIES OF MERCHANTABILITY,
FITNESS FOR A PARTICULAR PURPOSE AND NONINFRINGEMENT. IN NO EVENT SHALL THE
AUTHORS OR COPYRIGHT HOLDERS BE LIABLE FOR ANY CLAIM, DAMAGES OR OTHER
LIABILITY, WHETHER IN AN ACTION OF CONTRACT, TORT OR OTHERWISE, ARISING FROM,
OUT OF OR IN CONNECTION WITH THE SOFTWARE OR THE USE OR OTHER DEALINGS IN THE
SOFTWARE. -->
<robot name="jdamr">
    <!-- 로봇의 본체 -->
    <link name="body_link">
        <visual>
            <origin rpy="0 0 0" xyz="0 0 0"/> <!-- rpy: roll pitch yaw origin: origin point-->
            <geometry>
                <box size="1 0.6 0.3"/>  <!-- 박스 크기 -->
            </geometry>
            <material name="red">
                <color rgba="1 0 0 1"/>
            </material>
        </visual>
    </link>

    <!-- 첫 번째 바퀴 (왼쪽 앞) -->
    <joint name="wheel1_joint" type="continuous">
        <parent link="body_link"/>
        <child link="wheel1_link"/>
        <origin xyz="-0.3 -0.35 -0.1" rpy="0 0 0"/>
        <axis xyz="0 1 0"/>
    </joint>
    <link name="wheel1_link">
        <visual>
            <origin rpy="1.570795 0 0" xyz="0 0 0"/>
            <geometry>
                <cylinder length="0.1" radius="0.15"/>
            </geometry>
            <material name="yellow">
                <color rgba="1 1 0 1"/>
            </material>
        </visual>
    </link>

    <!-- 두 번째 바퀴 (오른쪽 앞) -->
    <joint name="wheel2_joint" type="continuous">
        <parent link="body_link"/>
        <child link="wheel2_link"/>
        <origin xyz="0.3 -0.35 -0.1" rpy="0 0 0"/>
        <axis xyz="0 1 0"/>
    </joint>
    <link name="wheel2_link">
        <visual>
            <origin rpy="1.570795 0 0" xyz="0 0 0"/>
            <geometry>
                <cylinder length="0.1" radius="0.15"/>
            </geometry>
            <material name="yellow">
                <color rgba="1 1 0 1"/>
            </material>
        </visual>
    </link>

    <!-- 세 번째 바퀴 (왼쪽 뒤) -->
    <joint name="wheel3_joint" type="continuous">
        <parent link="body_link"/>
        <child link="wheel3_link"/>
        <origin xyz="-0.3 0.35 -0.1" rpy="0 0 0"/>
        <axis xyz="0 1 0"/>
    </joint>
    <link name="wheel3_link">
        <visual>
            <origin rpy="1.570795 0 0" xyz="0 0 0"/>
            <geometry>
                <cylinder length="0.1" radius="0.15"/>
            </geometry>
            <material name="yellow">
                <color rgba="1 1 0 1"/>
            </material>
        </visual>
    </link>

    <!-- 네 번째 바퀴 (오른쪽 뒤) -->
    <joint name="wheel4_joint" type="continuous">
        <parent link="body_link"/>
        <child link="wheel4_link"/>
        <origin xyz="0.3 0.35 -0.1" rpy="0 0 0"/>
        <axis xyz="0 1 0"/>
    </joint>
    <link name="wheel4_link">
        <visual>
            <origin rpy="1.570795 0 0" xyz="0 0 0"/>
            <geometry>
                <cylinder length="0.1" radius="0.15"/>
            </geometry>
            <material name="yellow">
                <color rgba="1 1 0 1"/>
            </material>
        </visual>
    </link>

    <!-- 첫 번째 바퀴의 transmission -->
    <transmission name="wheel1_transmission">
        <type>transmission_interface/SimpleTransmission</type>
        <joint name="wheel1_joint">
            <hardwareInterface>hardware_interface/VelocityJointInterface</hardwareInterface>
        </joint>
        <actuator name="wheel1_motor">
            <hardwareInterface>hardware_interface/VelocityJointInterface</hardwareInterface>
        </actuator>
    </transmission>

    <!-- 두 번째 바퀴의 transmission -->
    <transmission name="wheel2_transmission">
        <type>transmission_interface/SimpleTransmission</type>
        <joint name="wheel2_joint">
            <hardwareInterface>hardware_interface/VelocityJointInterface</hardwareInterface>
        </joint>
        <actuator name="wheel2_motor">
            <hardwareInterface>hardware_interface/VelocityJointInterface</hardwareInterface>
        </actuator>
    </transmission>

    <!-- 세 번째 바퀴의 transmission -->
    <transmission name="wheel3_transmission">
        <type>transmission_interface/SimpleTransmission</type>
        <joint name="wheel3_joint">
            <hardwareInterface>hardware_interface/VelocityJointInterface</hardwareInterface>
        </joint>
        <actuator name="wheel3_motor">
            <hardwareInterface>hardware_interface/VelocityJointInterface</hardwareInterface>
        </actuator>
    </transmission>

    <!-- 네 번째 바퀴의 transmission -->
    <transmission name="wheel4_transmission">
        <type>transmission_interface/SimpleTransmission</type>
        <joint name="wheel4_joint">
            <hardwareInterface>hardware_interface/VelocityJointInterface</hardwareInterface>
        </joint>
        <actuator name="wheel4_motor">
            <hardwareInterface>hardware_interface/VelocityJointInterface</hardwareInterface>
        </actuator>
    </transmission>
</robot>