<?xml version="1.0" ?>
<!-- /*MIT License

Copyright (c) 2024 JD edu. http://jdedu.kr author: conner.jeong@gmail.com
     
Permission is hereby granted, free of charge, to any person obtaining a copy
of this software and associated documentation files (the "Software"), to deal
in the Software without restriction, including without limitation the rights
to use, copy, modify, merge, publish, distribute, sublicense, and/or sell
copies of the Software, and to permit persons to whom the Software is
furnished to do so, subject to the following conditions:
     
The above copyright notice and this permission notice shall be included in all
copies or substantial portions of the Software.
     
THE SOFTWARE IS PROVIDED "AS IS", WITHOUT WARRANTY OF ANY KIND, EXPRESS OR
IMPLIED, INCLUDING BUT NOT LIMITED TO THE WARRANTIES OF MERCHANTABILITY,
FITNESS FOR A PARTICULAR PURPOSE AND NONINFRINGEMENT. IN NO EVENT SHALL THE
AUTHORS OR COPYRIGHT HOLDERS BE LIABLE FOR ANY CLAIM, DAMAGES OR OTHER
LIABILITY, WHETHER IN AN ACTION OF CONTRACT, TORT OR OTHERWISE, ARISING FROM,
OUT OF OR IN CONNECTION WITH THE SOFTWARE OR THE USE OR OTHER DEALINGS IN TH
SOFTWARE.*/-->
<robot name="jdamr">
    <!-- robot body link  -->
    <link name="body_link">
        <visual>
            <origin rpy="0 0 0" xyz="0 0 0"/> <!-- rpy: roll pitch yaw origin: origin point-->
            <geometry>
                <box size="1 0.6 0.3"/>  <!-- box size -->
            </geometry>
            <material name="red">
                <color rgba="1 0 0 1"/>
            </material>
        </visual>
    </link>
     <joint name="wheel1_joint" type="continuous">
        <parent link="body_link"/>
        <child link="wheel1_link" />
        <origin xyz="-0.3 -0.35 -0.1" rpy="0 0 0"/>
        <axis xyz="0 1 0" />
    </joint>
    <link name="wheel1_link">
        <visual>
            <origin rpy="1.570795 0 0" xyz="0 0 0"/>
            <geometry>
                <cylinder length="0.1" radius="0.15"/>
            </geometry>
            <material name="yellow">
                <color rgba="1 1 0 1"/>
            </material>
        </visual>
    </link>
         <joint name="wheel2_joint" type="continuous">
        <parent link="body_link"/>
        <child link="wheel2_link" />
        <origin xyz="0.3 -0.35 -0.1" rpy="0 0 0"/>
        <axis xyz="0 1 0" />
    </joint>
    <link name="wheel2_link">
        <visual>
            <origin rpy="1.570795 0 0" xyz="0 0 0"/>
            <geometry>
                <cylinder length="0.1" radius="0.15"/>
            </geometry>
            <material name="yellow">
                <color rgba="1 1 0 1"/>
            </material>
        </visual>
    </link>
</robot>